<?xml version="1.0" ?>
<!-- =================================================================================== -->
<!-- |    This document was autogenerated by xacro from /home/brayan/catkin_ws/src/rockbreaker_arm_simulator/rockbreaker_description/urdf/rockbreaker_arm.urdf.xacro | -->
<!-- |    EDITING THIS FILE BY HAND IS NOT RECOMMENDED                                 | -->
<!-- =================================================================================== -->
<robot name="rockbreaker_arm">
    <!-- ros_control plugin -->
    <gazebo>
        <plugin filename="libgazebo_ros_control.so" name="gazebo_ros_control">
            <robotNamespace>/</robotNamespace>
            <robotSimType>gazebo_ros_control/DefaultRobotHWSim</robotSimType>
        </plugin>
    </gazebo>
    <!-- Link1 -->
    <!-- <gazebo reference="link1">
    <material>Gazebo/Orange</material>
  </gazebo> -->
    <!-- Link2 -->
    <!-- <gazebo reference="link2">
    <mu1>0.2</mu1>
    <mu2>0.2</mu2>
    <material>Gazebo/Black</material>
  </gazebo> -->
    <!-- Link3 -->
    <!-- <gazebo reference="link3">
    <mu1>0.2</mu1>
    <mu2>0.2</mu2>
    <material>Gazebo/Orange</material>
  </gazebo> -->
    <!-- camera_link -->
    <!-- <gazebo reference="camera_link">
    <mu1>0.2</mu1>
    <mu2>0.2</mu2>
    <material>Gazebo/Red</material>
  </gazebo> -->
    <model name="kinect">
        <static>true</static>
        <pose>0 0 0.036 0 0 0</pose>
        <link name="link_camera">
            <inertial>
                <mass>0.1</mass>
            </inertial>
            <collision name="collision">
                <geometry>
                    <box>
                        <size>0.073000 0.276000 0.072000</size>
                    </box>
                </geometry>
            </collision>
            <visual name="visual">
                <geometry>
                    <mesh>
                        <uri>model://kinect/meshes/kinect.dae</uri>
                    </mesh>
                </geometry>
            </visual>
            <sensor name="camera" type="depth">
                <plugin filename="libgazebo_ros_openni_kinect.so" name="camera_plugin">
                    <baseline>0.2</baseline>
                    <alwaysOn>true</alwaysOn>
                    <!-- Keep this zero, update_rate in the parent <sensor> tag
            will control the frame rate. -->
                    <updateRate>0.0</updateRate>
                    <cameraName>camera_ir</cameraName>
                    <imageTopicName>/camera/color/image_raw</imageTopicName>
                    <cameraInfoTopicName>/camera/color/camera_info</cameraInfoTopicName>
                    <depthImageTopicName>/camera/depth/image_raw</depthImageTopicName>
                    <depthImageCameraInfoTopicName>/camera/depth/camera_info</depthImageCameraInfoTopicName>
                    <pointCloudTopicName>/camera/depth/points</pointCloudTopicName>
                    <frameName>camera_link</frameName>
                    <pointCloudCutoff>0.5</pointCloudCutoff>
                    <pointCloudCutoffMax>3000.0</pointCloudCutoffMax>
                    <distortionK1>0</distortionK1>
                    <distortionK2>0</distortionK2>
                    <distortionK3>0</distortionK3>
                    <distortionT1>0</distortionT1>
                    <distortionT2>0</distortionT2>
                    <CxPrime>0</CxPrime>
                    <Cx>0</Cx>
                    <Cy>0</Cy>
                    <focalLength>0</focalLength>
                    <hackBaseline>0</hackBaseline>
                </plugin>
                <update_rate>20</update_rate>
                <camera>
                    <horizontal_fov>1.047198</horizontal_fov>
                    <image>
                        <width>640</width>
                        <height>480</height>
                        <format>R8G8B8</format>
                    </image>
                    <clip>
                        <near>0.05</near>
                        <far>3000</far>
                    </clip>
                </camera>
            </sensor>
        </link>
    </model>
    <!-- Base Fija -->
    <link name="world" />
    <!-- Base Link -->
    <joint name="fixed" type="fixed">
        <parent link="world" />
        <child link="rockbreaker_base" />
        <origin rpy="0 0 1.571" xyz="-3 -3 15.756649" />
    </joint>
    <!-- Base Fija -->
    <link name="rockbreaker_base">
        <visual>
            <origin rpy="0 0 0" xyz="0 0 0" />
            <geometry>
                <!--<mesh filename = "file:///home/kyungki/workspace/catkin_ws/src/velodyne_simulator/velodyne_description/meshes/excavator-1.dae"/>-->
                <mesh filename="package://rockbreaker_arm_simulator/rockbreaker_description/meshes/basefija.dae" scale="1 1 1" />
            </geometry>
        </visual>
        <collision>
            <origin rpy="0 0 0" xyz="0 0 0" />
            <geometry>
                <mesh filename="package://rockbreaker_arm_simulator/rockbreaker_description/meshes/basefija.dae" scale="1 1 1" />
            </geometry>
        </collision>
        <inertial>
            <origin xyz="0 0 0.3" rpy="0 0 0" />
            <mass value="1000" />
            <!-- <inertial>
      <mass value="${mass}" /> -->
            <inertia ixx="541.6664499999999" ixy="0.0" ixz="0.0" iyy="541.6664499999999" iyz="0.0" izz="1041.66625" />
            <!-- </inertial> -->
        </inertial>
    </link>
    <!-- Base Rotatoria -->
    <link name="rockbreaker_baserotatoria">
        <visual>
            <origin rpy="0 0 3.14" xyz="0 0 -0.2" />
            <geometry>
                <!-- <mesh filename = "file:///home/kyungki/workspace/catkin_ws/src/velodyne_simulator/velodyne_description/meshes/excavator-1.dae"/> -->
                <mesh filename="package://rockbreaker_arm_simulator/rockbreaker_description/meshes/base_rotatoria.dae" scale="0.1 0.1 0.1" />
            </geometry>
        </visual>
        <collision>
            <origin rpy="0 0 3.14" xyz="0 0 -0.2" />
            <geometry>
                <mesh filename="package://rockbreaker_arm_simulator/rockbreaker_description/meshes/base_rotatoria.dae" scale="0.1 0.1 0.1" />
            </geometry>
        </collision>
        <inertial>
            <origin rpy="0 0 1.57" xyz="0 0 0.2" />
            <mass value="400" />
            <!-- <inertial>
      <mass value="${mass}" /> -->
            <inertia ixx="105.6666244" ixy="0.0" ixz="0.0" iyy="105.6666244" iyz="0.0" izz="130.6666144" />
            <!-- </inertial> -->
        </inertial>
    </link>
    <!-- Brazo A -->
    <link name="brazo_a">
        <visual>
            <origin rpy="0 0.6 1.57" xyz="0 0 -0.2" />
            <geometry>
                --&gt;
                <!--<mesh filename = "file:///home/kyungki/workspace/catkin_ws/src/velodyne_simulator/velodyne_description/meshes/excavator-1.dae"/>-->
                <mesh filename="package://rockbreaker_arm_simulator/rockbreaker_description/meshes/BrazoA_rockbreaker.dae" scale="1 1 1" />
            </geometry>
        </visual>
        <collision>
            <origin rpy="0 0.6 1.57" xyz="0 0 -0.2" />
            <geometry>
                <mesh filename="package://rockbreaker_arm_simulator/rockbreaker_description/meshes/BrazoA_rockbreaker.dae" scale="1 1 1" />
            </geometry>
        </collision>
        <inertial>
            <origin rpy="0 0.6 1.57" xyz="-0.4 -3.0 3.2" />
            <mass value="160" />
            <!-- <inertial>
      <mass value="${mass}" /> -->
            <inertia ixx="37.499985" ixy="0.0" ixz="0.0" iyy="525.7497897" iyz="0.0" izz="525.7497897" />
            <!-- </inertial> -->
        </inertial>
    </link>
    <!-- Brazo B -->
    <link name="brazo_b">
        <visual>
            <origin rpy="0 0.6 1.57" xyz="0 0 -0.2" />
            <geometry>
                <!--<mesh filename = "file:///home/kyungki/workspace/catkin_ws/src/velodyne_simulator/velodyne_description/meshes/excavator-1.dae"/>-->
                <mesh filename="package://rockbreaker_arm_simulator/rockbreaker_description/meshes/BrazoB_rockbreaker.dae" scale="1 1 1" />
            </geometry>
        </visual>
        <collision>
            <origin rpy="0 0.6 1.57" xyz="0 0 -0.2" />
            <geometry>
                <mesh filename="package://rockbreaker_arm_simulator/rockbreaker_description/meshes/BrazoB_rockbreaker.dae" scale="1 1 1" />
            </geometry>
        </collision>
        <inertial>
            <origin rpy="0 0.6 1.57" xyz="0.5 -4.0 2.8" />
            <mass value="80" />
            <!-- <inertial>
      <mass value="${mass}" /> -->
            <inertia ixx="21.666657999999998" ixy="0.0" ixz="0.0" iyy="254.999898" iyz="0.0" izz="246.66656799999998" />
            <!-- </inertial> -->
        </inertial>
    </link>
    <!-- Hydraulic Hammer -->
    <link name="h_hammer">
        <visual>
            <origin rpy="0 1.57 1.57" xyz="0 0 -0.2" />
            <geometry>
                <!--<mesh filename = "file:///home/kyungki/workspace/catkin_ws/src/velodyne_simulator/velodyne_description/meshes/excavator-1.dae"/>-->
                <mesh filename="package://rockbreaker_arm_simulator/rockbreaker_description/meshes/Hydraulic_Hammer.dae" scale="1 1 1" />
            </geometry>
        </visual>
        <collision>
            <origin rpy="0 1.57 1.57" xyz="0 0 -0.2" />
            <geometry>
                <mesh filename="package://rockbreaker_arm_simulator/rockbreaker_description/meshes/Hydraulic_Hammer.dae" scale="1 1 1" />
            </geometry>
        </collision>
        <inertial>
            <origin rpy="0 1.57 1.57" xyz="-0.4 -1.5 0.2" />
            <mass value="40" />
            <!-- <inertial>
      <mass value="${mass}" /> -->
            <inertia ixx="18.96665908" ixy="0.0" ixz="0.0" iyy="16.66666" iyz="0.0" izz="8.966663080000002" />
            <!-- </inertial> -->
        </inertial>
    </link>
    <!-- Effector -->
    <!-- <link name="effector_hammer" >
      <visual>
        <origin xyz="0 0 0" rpy="-1.57 0 0"/>
        <geometry>  -->
    <!--<mesh filename = "file:///home/kyungki/workspace/catkin_ws/src/velodyne_simulator/velodyne_description/meshes/excavator-1.dae"/>-->
    <!-- <mesh filename="package://rockbreaker_arm_simulator/rockbreaker_description/meshes/Hammer_Punta.dae" scale="1 1 1"/>
        </geometry>
      </visual>
      <collision>
        <origin xyz="0 0 0" rpy="-1.57 0 0"/>
        <geometry>
          <mesh filename="package://rockbreaker_arm_simulator/rockbreaker_description/meshes/Hammer_Punta.dae" scale="1 1 1"/>
        </geometry>
      </collision>
      <inertial>
        <origin xyz="0 0 0" rpy="-1.57 0 0"/>
        <mass value="2"/>
      <xacro:box_inertia x="0.2" y="0.2" z="0.2" mass="2"/>
      </inertial>
    </link> -->
    <!-- Effector 2 -->
    <!-- <link name="effector_hammer2" >
      <visual>
        <origin xyz="0 0 0" rpy="-1.57 0 0"/>
        <geometry>  -->
    <!--<mesh filename = "file:///home/kyungki/workspace/catkin_ws/src/velodyne_simulator/velodyne_description/meshes/excavator-1.dae"/>-->
    <!-- <mesh filename="package://rockbreaker_arm_simulator/rockbreaker_description/meshes/Hammer_Punta.dae" scale="1 1 1"/>
        </geometry>
      </visual>
      <collision>
        <origin xyz="0 0 0" rpy="-1.57 0 0"/>
        <geometry>
          <mesh filename="package://rockbreaker_arm_simulator/rockbreaker_description/meshes/Hammer_Punta.dae" scale="1 1 1"/>
        </geometry>
      </collision>
      <inertial>
        <origin xyz="0 0 0" rpy="-1.57 0 0"/>
        <mass value="2"/>
      <xacro:box_inertia x="0.2" y="0.2" z="0.2" mass="2"/>
      </inertial>
    </link> -->
    <!-- <link name="base_ir_front">
    <collision>
      <origin xyz="0 0 0" rpy="0 0 0"/>
      <geometry>
        <box size="0.01 0.01 0.01"/>
      </geometry>
    </collision>    
    <visual>
      <origin xyz="0 0 0" rpy="0 0 0"/>
      <geometry>
        <box size="0.01 0.01 0.01"/>
      </geometry>
    </visual>    
    <inertial>
      <mass value="1e-5" />
      <origin xyz="0 0 0" rpy="0 0 0"/>
      <inertia ixx="1e-6" ixy="0" ixz="0" iyy="1e-6" iyz="0"      izz="1e-6" />
    </inertial>
  </link>

  <gazebo reference="base_ir_front">        
   <sensor type="ray" name="Sonar">
      <pose>0 0 0 0 0 0</pose>
      <visualize>true</visualize>
      <update_rate>20</update_rate>
      <ray>
         <scan>
            <horizontal>
               <samples>10</samples>
               <resolution>1</resolution> 
               <min_angle>-0.25835</min_angle>
               <max_angle>0.25835</max_angle>
            </horizontal>
            <vertical>
               <samples>10</samples>
               <resolution>1</resolution> 
               <min_angle>-0.25835</min_angle>
               <max_angle>0.25835</max_angle> 
            </vertical>
         </scan>
         <range>
            <min>0.01</min>
            <max>7</max>
            <resolution>0.01</resolution>
         </range>
      </ray>
      <plugin filename="libgazebo_ros_range.so" name="gazebo_ros_range">
         <gaussianNoise>0.005</gaussianNoise>
         <alwaysOn>true</alwaysOn>
         <updateRate>20</updateRate>
         <topicName>/sensor</topicName>
         <frameName>base_ir_front</frameName>
         <radiation>ultrasound</radiation>
         <fov>0.4967</fov>
      </plugin>
    </sensor>  
  </gazebo>

  <joint name="ir_front_joint" type="fixed">
    <axis xyz="0 0 0" />
    <origin rpy="1.57 0 0" xyz="0 0 0" />
    <parent link="brazo_a"/>
    <child link="base_ir_front"/>
  </joint> -->
    <!-- Hydraulic Hammer Punta -->
    <!-- <link name="h_punta" >
    <visual>
      <origin xyz="0 0 0" rpy="-0.6 0 0"/>
      <geometry> -->
    <!--<mesh filename = "file:///home/kyungki/workspace/catkin_ws/src/velodyne_simulator/velodyne_description/meshes/excavator-1.dae"/>-->
    <!-- <mesh filename="package://rockbreaker_arm_simulator/rockbreaker_description/meshes/Hydraulic_Hammer.dae" scale="1 1 1"/>
      </geometry>
    </visual>
    <collision>
      <origin xyz="0 0 0" rpy="-0.6 0 0"/>
      <geometry>
        <mesh filename="package://rockbreaker_arm_simulator/rockbreaker_description/meshes/Hydraulic_Hammer.dae" scale="1 1 1"/>
      </geometry>
    </collision>
    <inertial>
      <origin xyz="0 0 0"/>
      <mass value="5"/>
      <inertia ixx="3.0" ixy="0.0" ixz="0.0"
               iyy="3.0" iyz="0.0" 
               izz="3.0" />
    </inertial>
  </link> -->
    <joint name="joint_base_rockbreaker" type="revolute">
        <axis xyz="0 0 1" />
        <limit effort="1000000" lower="-1.57" upper="1.57" velocity="1" />
        <parent link="rockbreaker_base" />
        <child link="rockbreaker_baserotatoria" />
        <origin rpy="0 0 0" xyz="0 0 1.1 " />
        <dynamics damping="1.0" friction="0.1" />
    </joint>
    <joint name="joint_brazoa" type="revolute">
        <axis xyz="1 0 0" />
        <limit effort="1000000" lower="-2.14" upper="2.14" velocity="1" />
        <parent link="rockbreaker_baserotatoria" />
        <child link="brazo_a" />
        <origin rpy="0 0 0" xyz="0.375 0.05 1.2" />
        <dynamics damping="1.0" friction="0.1" />
    </joint>
    <joint name="joint_brazob" type="revolute">
        <axis xyz="1 0 0" />
        <limit effort="100000" lower="-2.14" upper="2.14" velocity="1" />
        <parent link="brazo_a" />
        <child link="brazo_b" />
        <origin rpy="0 0 0" xyz="-0.9 -6.75 4.6" />
        <dynamics damping="1.0" friction="0.1" />
    </joint>
    <joint name="joint_hammer" type="revolute">
        <axis xyz="1 0 0" />
        <limit effort="100000" lower="-2.14" upper="2.14" velocity="1" />
        <parent link="brazo_b" />
        <child link="h_hammer" />
        <origin rpy="0 0 0" xyz="0.875 -6.82 4.68" />
        <dynamics damping="1.0" friction="0.1" />
    </joint>
    <!-- <joint name="joint_effector" type="revolute" >
    <axis xyz="1 0 0"/>
    <limit effort="100000" lower="-1.14" upper="1.14" velocity="10"/>
    <parent link="h_hammer" />
    <child link="effector_hammer" />
    <origin xyz="-0.36 -2.4 0.26" rpy="0 0 0" />
    <dynamics damping="${damping_value}" friction="${friction_value}"/> 
  </joint>

   <joint name="joint_effector1" type="revolute" >
    <axis xyz="1 0 0"/>
    <limit effort="100000" lower="-1.14" upper="1.14" velocity="10"/>
    <parent link="effector_hammer" />
    <child link="effector_hammer2" />
    <origin xyz="-0.36 -2.4 0.26" rpy="0 0 0" />
    <dynamics damping="${damping_value}" friction="${friction_value}"/> 
  </joint> -->
    <!-- <joint name="joint_punta" type="revolute" >
    <axis xyz="0 0 1"/>
    <limit effort="100000.0" lower="0.0" upper="3.1415" velocity="10000.0"/>
    <parent link="h_hammer" />
    <child link="h_punta" />
    <origin xyz="0.425 -1.65 -1.88" rpy="0 0 0" /> 
  </joint> -->
    <transmission name="tran1">
        <type>transmission_interface/SimpleTransmission</type>
        <joint name="joint_base_rockbreaker">
            <hardwareInterface>hardware_interface/PositionJointInterface</hardwareInterface>
        </joint>
        <actuator name="motor1">
            <hardwareInterface>hardware_interface/PositionJointInterface</hardwareInterface>
            <mechanicalReduction>1</mechanicalReduction>
        </actuator>
    </transmission>
    <transmission name="tran2">
        <type>transmission_interface/SimpleTransmission</type>
        <joint name="joint_brazoa">
            <hardwareInterface>hardware_interface/PositionJointInterface</hardwareInterface>
        </joint>
        <actuator name="motor2">
            <hardwareInterface>hardware_interface/PositionJointInterface</hardwareInterface>
            <mechanicalReduction>1</mechanicalReduction>
        </actuator>
    </transmission>
    <transmission name="tran3">
        <type>transmission_interface/SimpleTransmission</type>
        <joint name="joint_brazob">
            <hardwareInterface>hardware_interface/PositionJointInterface</hardwareInterface>
        </joint>
        <actuator name="motor3">
            <hardwareInterface>hardware_interface/PositionJointInterfacee</hardwareInterface>
            <mechanicalReduction>1</mechanicalReduction>
        </actuator>
    </transmission>
    <transmission name="tran4">
        <type>transmission_interface/SimpleTransmission</type>
        <joint name="joint_hammer">
            <hardwareInterface>hardware_interface/PositionJointInterface</hardwareInterface>
        </joint>
        <actuator name="motor4">
            <hardwareInterface>hardware_interface/PositionJointInterface</hardwareInterface>
            <mechanicalReduction>1</mechanicalReduction>
        </actuator>
    </transmission>
    <!--
  <xacro:include filename="$(find velodyne_description)/urdf/VLP-16.urdf.xacro"/>
  <xacro:VLP-16 parent="excavator_base" name="velodyne" topic="/velodyne_points" organize_cloud="${organize_cloud}" hz="10" samples="440" gpu="${gpu}" >
    <origin xyz="1 2.7 1.2" rpy="0 0 0" />
  </xacro:VLP-16>
  -->
    <!-- <xacro:include filename=rockbreaker)/urdf/HDL-32E.urdf.xacro"/> -->
    <!-- <xacro:include filename="$(find lidar_description)/urdf/OS0-64.urdf.xacro"/>
   <xacro:OS0-64 parent="rockbreaker_base" name="os0_sensor" topic="/os0_cloud_node/points"  hz="10" samples="512" >
    <origin xyz="3 -13 0" rpy="0 0 1.57" />
  </xacro:OS0-64> -->
    <!-- <xacro:include filename=rockbreaker)/urdf/stereo_camera.urdf.xacro"/>
  <xacro:include filename=rockbreaker)/urdf/VLP-16.urdf.xacro"/>

  <xacro:stereo_camera_sensor parent="excavator_base" name="camera_front" >
    <origin xyz="0.8 0 1.5" rpy="0 0 ${-M_PI}" />
  </xacro:stereo_camera_sensor> -->
    <!--
  <xacro:HDL-32E parent="excavator_base" name="velodyne_top" topic="/top/velodyne_points2" organize_cloud="${organize_cloud}" hz="10" samples="220" min_angle="${-M_PI}" max_angle="${M_PI}" gpu="${gpu}" >
    <origin xyz="0 0 2.8" rpy="0 0 0" />
  </xacro:HDL-32E>

  <xacro:camera_sensor parent="excavator_base" name="camera_left_front" >
    <origin xyz="-0.8 2.7 1.2" rpy="0 0 ${M_PI/2}" />
  </xacro:camera_sensor>


  <xacro:camera_sensor parent="excavator_base" name="camera_left_back" >
    <origin xyz="-0.8 -3 1.2" rpy="0 0 ${-M_PI/2}" />
  </xacro:camera_sensor>

  <xacro:camera_sensor parent="excavator_base" name="camera_right_back" >
    <origin xyz="0.8 -3 1.2" rpy="0 0 ${-M_PI/2}" />
  </xacro:camera_sensor>
  -->
    <!-- <link name="camera_link">
    <visual>
      <origin xyz="0 0 0" rpy="0 0 0"/>
      <geometry>
        <box size="1 1 1"/>
      </geometry>
    </visual>
    <collision>
      <origin xyz="0 0 0" rpy="0 0 0"/>
      <geometry>
        <box size="1 1 1"/>
      </geometry>
    </collision>
    <inertial>
      <origin xyz="0 0 0" rpy="0 0 0"/>
      <mass value="0.035"/>
      <inertia ixx="0.001"  ixy="0"  ixz="0" iyy="0.001" iyz="0" izz="0.001" />
    </inertial>
  </link>

  <joint name="camera_joint" type="fixed">
    <parent link="rockbreaker_baserotatoria"/>
    <child link="camera_link"/>
    <origin xyz="1 1 1" rpy="0 0 0"/>
  </joint>

  <link name="camera_depth_frame"/>

  <joint name="camera_depth_joint" type="fixed">
    <origin xyz="0 0 0" rpy="${-pi/2} 0 ${-pi/2}"/>
    <parent link="camera_link"/>
    <child link="camera_depth_frame"/>
  </joint>

  <gazebo reference="camera_link">
  <sensor name="depth_camera" type="depth">
    <update_rate>20</update_rate>
    <camera>
      <horizontal_fov>1.047198</horizontal_fov>
      <image>
        <width>640</width>
        <height>480</height>
        <format>R8G8B8</format>
      </image>
      <clip>
        <near>0.05</near>
        <far>3</far>
      </clip>
    </camera>
    <plugin name="depth_camera_controller" filename="libgazebo_ros_openni_kinect.so">
      <baseline>0.2</baseline>
      <alwaysOn>true</alwaysOn>
      <updateRate>1.0</updateRate>
      <cameraName>kine_ir</cameraName>
      <imageTopicName>/kine/color/image_raw</imageTopicName>
      <cameraInfoTopicName>/kine/color/camera_info</cameraInfoTopicName>
      <depthImageTopicName>/kine/depth/image_raw</depthImageTopicName>
      <depthImageInfoTopicName>/kine/depth/camera_info</depthImageInfoTopicName>
      <pointCloudTopicName>/kine/depth/points</pointCloudTopicName>
      <frameName>kine_frame</frameName>
      <pointCloudCutoff>0.5</pointCloudCutoff>
      <pointCloudCutoffMax>3.0</pointCloudCutoffMax>
      <distortionK1>0.00000001</distortionK1>
      <distortionK2>0.00000001</distortionK2>
      <distortionK3>0.00000001</distortionK3>
      <distortionT1>0.00000001</distortionT1>
      <distortionT2>0.00000001</distortionT2>
      <CxPrime>0</CxPrime>
      <Cx>0</Cx>
      <Cy>0</Cy>
      <focalLength>0</focalLength>
      <hackBaseline>0</hackBaseline>
    </plugin>
  </sensor>
</gazebo> -->
</robot>

